Workbook

Sheet Matriz Setup
A2: LINHA 01 | B2: AGUA SANITARIA 1L | C2: AGUA SANITARIA 2L | D2: ALVEJANTE S/ CLORO 1L | E2: ALVEJANTE S/ CLORO 2L
A3: AGUA SANITARIA 1L | B3: 0.0069444444 | C3: 0.034722222 | D3: 0.013888889 | E3: 0.034722222
A4: AGUA SANITARIA 2L | B4: 0.034722222 | C4: 0.0069444444 | D4: 0.034722222 | E4: 0.013888889
A5: ALVEJANTE S/ CLORO 1L | B5: 0.013888889 | C5: 0.034722222 | D5: 0.0069444444 | E5: 0.034722222
A6: ALVEJANTE S/ CLORO 2L | B6: 0.034722222 | C6: 0.013888889 | D6: 0.034722222 | E6: 0.0069444444
A9: LINHA 02 | B9: AGUA SANITARIA 5L | C9: ALVEJANTE S/ CLORO 3L | D9: DESINFETANTE 5L
A10: AGUA SANITARIA 5L
A11: ALVEJANTE S/ CLORO 3L
A12: DESINFETANTE 5L
A15: LINHA 03 | B15: AMACIANTE 2L | C15: DESINFETANTE 2L | D15: ELIMINADOR DE ODORES 2L | E15: LAVA ROUPAS 2L | F15: LIMP PERF 2L
A16: AMACIANTE 2L
A17: DESINFETANTE 2L
A18: ELIMINADOR DE ODORES 2L
A19: LAVA ROUPAS 2L
A20: LIMP PERF 2L
A23: LINHA 04 | B23: DESINFETANTE 500ML | C23: DETERGENTE 1L | D23: DETERGENTE 500ML
A24: DESINFETANTE 500ML
A25: DETERGENTE 1L
A26: DETERGENTE 500ML
A29: LINHA 05 | B29: ALVEJANTE S/ CLORO 5L | C29: AMAC. CONC. 3L | D29: AMACIANTE 5L | E29: DETERGENTE 5L | F29: LAVA ROUPAS 3L | G29: LAVA ROUPAS 5L
A30: ALVEJANTE S/ CLORO 5L
A31: AMAC. CONC. 3L
A32: AMACIANTE 5L
A33: DETERGENTE 5L
A34: LAVA ROUPAS 3L
A35: LAVA ROUPAS 5L
A38: LINHA 06 | B38: AMAC. CONC. 1,5L | C38: AMAC. CONC. 1L | D38: AMAC. CONC. 500ML | E38: DESENG. PULVER. 500ML | F38: DESENG. RECARGA 500ML | G38: DESENG. SQUEEZE 1L | H38: DESENG. SQUEEZE 500ML | I38: LAVA ROUPAS 1L | J38: LIMP PERF 1L | K38: LIMP PERF 500ML | L38: LIMPA VIDROS PULVER. 500ML | M38: LIMPA VIDROS RECARGA 500ML | N38: LIMPA VIDROS SQUEEZE 500ML | O38: MULTI USO 1L | P38: MULTI USO 500ML
A39: AMAC. CONC. 1,5L
A40: AMAC. CONC. 1L
A41: AMAC. CONC. 500ML
A42: DESENG. PULVER. 500ML
A43: DESENG. RECARGA 500ML
A44: DESENG. SQUEEZE 1L
A45: DESENG. SQUEEZE 500ML
A46: LAVA ROUPAS 1L
A47: LIMP PERF 1L
A48: LIMP PERF 500ML
A49: LIMPA VIDROS PULVER. 500ML
A50: LIMPA VIDROS RECARGA 500ML
... A53: MULTI USO 500ML

Sheet Linha 1
B1: Setup | C1: Tempo
B2: =CONCATENATE('Matriz Setup'!A3,'Matriz Setup'!B2) -> AGUA SANITARIA 1LAGUA SANITARIA 1L | C2: 0.0069444444
B3: =CONCATENATE('Matriz Setup'!A3,'Matriz Setup'!C2) -> AGUA SANITARIA 1LAGUA SANITARIA 2L | C3: 0.034722222
B4: =CONCATENATE('Matriz Setup'!A3,'Matriz Setup'!D2) -> AGUA SANITARIA 1LALVEJANTE S/ CLORO 1L | C4: 0.013888889
B5: =CONCATENATE('Matriz Setup'!A3,'Matriz Setup'!E2) -> AGUA SANITARIA 1LALVEJANTE S/ CLORO 2L | C5: 0.034722222
B6: =CONCATENATE('Matriz Setup'!A4,'Matriz Setup'!B2) -> AGUA SANITARIA 2LAGUA SANITARIA 1L | C6: 0.034722222
B7: =CONCATENATE('Matriz Setup'!A4,'Matriz Setup'!C2) -> AGUA SANITARIA 2LAGUA SANITARIA 2L | C7: 0.0069444444
B8: =CONCATENATE('Matriz Setup'!A4,'Matriz Setup'!D2) -> AGUA SANITARIA 2LALVEJANTE S/ CLORO 1L | C8: 0.034722222
B9: =CONCATENATE('Matriz Setup'!A4,'Matriz Setup'!E2) -> AGUA SANITARIA 2LALVEJANTE S/ CLORO 2L | C9: 0.013888889
B10: =CONCATENATE('Matriz Setup'!A5,'Matriz Setup'!B2) -> ALVEJANTE S/ CLORO 1LAGUA SANITARIA 1L | C10: 0.013888889
B11: =CONCATENATE('Matriz Setup'!A5,'Matriz Setup'!C2) -> ALVEJANTE S/ CLORO 1LAGUA SANITARIA 2L | C11: 0.034722222
B12: =CONCATENATE('Matriz Setup'!A5,'Matriz Setup'!D2) -> ALVEJANTE S/ CLORO 1LALVEJANTE S/ CLORO 1L | C12: 0.0069444444
B13: =CONCATENATE('Matriz Setup'!A5,'Matriz Setup'!E2) -> ALVEJANTE S/ CLORO 1LALVEJANTE S/ CLORO 2L | C13: 0.034722222
B14: =CONCATENATE('Matriz Setup'!A6,'Matriz Setup'!B2) -> ALVEJANTE S/ CLORO 2LAGUA SANITARIA 1L | C14: 0.034722222
B15: =CONCATENATE('Matriz Setup'!A6,'Matriz Setup'!C2) -> ALVEJANTE S/ CLORO 2LAGUA SANITARIA 2L | C15: 0.013888889
B16: =CONCATENATE('Matriz Setup'!A6,'Matriz Setup'!D2) -> ALVEJANTE S/ CLORO 2LALVEJANTE S/ CLORO 1L | C16: 0.034722222
B17: =CONCATENATE('Matriz Setup'!A6,'Matriz Setup'!E2) -> ALVEJANTE S/ CLORO 2LALVEJANTE S/ CLORO 2L | C17: 0.0069444444
B23: LINHA 01 | C23: AGUA SANITARIA 1L | D23: AGUA SANITARIA 2L | E23: ALVEJANTE S/ CLORO 1L | F23: ALVEJANTE S/ CLORO 2L
B24: AGUA SANITARIA 1L | C24: 0.0069444444 | D24: 0.034722222 | E24: 0.013888889 | F24: 0.034722222
B25: AGUA SANITARIA 2L | C25: 0.034722222 | D25: 0.0069444444 | E25: 0.034722222 | F25: 0.013888889
B26: ALVEJANTE S/ CLORO 1L | C26: 0.013888889 | D26: 0.034722222 | E26: 0.0069444444 | F26: 0.034722222
B27: ALVEJANTE S/ CLORO 2L | C27: 0.034722222 | D27: 0.013888889 | E27: 0.034722222 | F27: 0.0069444444

Sheet Linha 2
B2: LINHA 02 | C2: AGUA SANITARIA 5L | D2: ALVEJANTE S/ CLORO 3L | E2: DESINFETANTE 5L | I2: AGUA SANITARIA 5L | J2: ALVEJANTE S/ CLORO 3L | K2: DESINFETANTE CAMPOS LAVANDA 5L | L2: DESINFETANTE ENERGIA 5L | M2: DESINFETANTE FL. DE EUCALIPTO 5L | N2: DESINFETANTE HARMONIA NATURAL 5L | O2: DESINFETANTE JARDIM FLORIDO 5L | P2: DESINFETANTE MARINE 5L | Q2: DESINFETANTE PAIXAO 5L
B3: AGUA SANITARIA 5L | C3: 0.013888889 | D3: 0.020833333 | E3: 0.020833333 | H3: AGUA SANITARIA 5L | I3: 0.013888889 | J3: 0.020833333 | K3: 0.020833333 | L3: 0.020833333 | M3: 0.020833333 | N3: 0.020833333 | O3: 0.020833333 | P3: 0.020833333 | Q3: 0.020833333
B4: ALVEJANTE S/ CLORO 3L | C4: 0.020833333 | D4: 0.013888889 | E4: 0.020833333 | H4: ALVEJANTE S/ CLORO 3L | I4: 0.020833333 | J4: 0.013888889 | K4: 0.020833333 | L4: 0.020833333 | M4: 0.020833333 | N4: 0.020833333 | O4: 0.020833333 | P4: 0.020833333 | Q4: 0.020833333
B5: DESINFETANTE 5L | C5: 0.020833333 | D5: 0.020833333 | E5: 0.013888889 | H5: DESINFETANTE CAMPOS LAVANDA 5L | I5: 0.020833333 | J5: 0.020833333 | K5: 0.013888889 | L5: 0.013888889 | M5: 0.013888889 | N5: 0.013888889 | O5: 0.013888889 | P5: 0.013888889 | Q5: 0.013888889
H6: DESINFETANTE ENERGIA 5L | I6: 0.020833333 | J6: 0.020833333 | K6: 0.013888889 | L6: 0.013888889 | M6: 0.013888889 | N6: 0.013888889 | O6: 0.013888889 | P6: 0.013888889 | Q6: 0.013888889
H7: DESINFETANTE FL. DE EUCALIPTO 5L | I7: 0.020833333 | J7: 0.020833333 | K7: 0.013888889 | L7: 0.013888889 | M7: 0.013888889 | N7: 0.013888889 | O7: 0.013888889 | P7: 0.013888889 | Q7: 0.013888889
H8: DESINFETANTE HARMONIA NATURAL 5L | I8: 0.020833333 | J8: 0.020833333 | K8: 0.013888889 | L8: 0.013888889 | M8: 0.013888889 | N8: 0.013888889 | O8: 0.013888889 | P8: 0.013888889 | Q8: 0.013888889
H9: DESINFETANTE JARDIM FLORIDO 5L | I9: 0.020833333 | J9: 0.020833333 | K9: 0.013888889 | L9: 0.013888889 | M9: 0.013888889 | N9: 0.013888889 | O9: 0.013888889 | P9: 0.013888889 | Q9: 0.013888889
H10: DESINFETANTE MARINE 5L | I10: 0.020833333 | J10: 0.020833333 | K10: 0.013888889 | L10: 0.013888889 | M10: 0.013888889 | N10: 0.013888889 | O10: 0.013888889 | P10: 0.013888889 | Q10: 0.013888889
H11: DESINFETANTE PAIXAO 5L | I11: 0.020833333 | J11: 0.020833333 | K11: 0.013888889 | L11: 0.013888889 | M11: 0.013888889 | N11: 0.013888889 | O11: 0.013888889 | P11: 0.013888889 | Q11: 0.013888889
B13: AGUA SANITARIA 5L | H13: AGUA SANITARIA 5L | J13: =CONCATENATE($B$13,H13) -> AGUA SANITARIA 5LAGUA SANITARIA 5L | K13: 0.013888889
B14: ALVEJANTE S/ CLORO 3L | H14: ALVEJANTE S/ CLORO 3L | J14: =CONCATENATE($B$13,H14) -> AGUA SANITARIA 5LALVEJANTE S/ CLORO 3L | K14: 0.020833333
B15: DESINFETANTE CAMPOS LAVANDA 5L | H15: DESINFETANTE CAMPOS LAVANDA 5L | J15: =CONCATENATE($B$13,H15) -> AGUA SANITARIA 5LDESINFETANTE CAMPOS LAVANDA 5L | K15: 0.020833333
B16: DESINFETANTE ENERGIA 5L | H16: DESINFETANTE ENERGIA 5L | J16: =CONCATENATE($B$13,H16) -> AGUA SANITARIA 5LDESINFETANTE ENERGIA 5L | K16: 0.020833333
B17: DESINFETANTE FL. DE EUCALIPTO 5L | H17: DESINFETANTE FL. DE EUCALIPTO 5L | J17: =CONCATENATE($B$13,H17) -> AGUA SANITARIA 5LDESINFETANTE FL. DE EUCALIPTO 5L | K17: 0.020833333
B18: DESINFETANTE HARMONIA NATURAL 5L | H18: DESINFETANTE HARMONIA NATURAL 5L | J18: =CONCATENATE($B$13,H18) -> AGUA SANITARIA 5LDESINFETANTE HARMONIA NATURAL 5L | K18: 0.020833333
B19: DESINFETANTE JARDIM FLORIDO 5L | H19: DESINFETANTE JARDIM FLORIDO 5L | J19: =CONCATENATE($B$13,H19) -> AGUA SANITARIA 5LDESINFETANTE JARDIM FLORIDO 5L | K19: 0.020833333
B20: DESINFETANTE MARINE 5L | H20: DESINFETANTE MARINE 5L | J20: =CONCATENATE($B$13,H20) -> AGUA SANITARIA 5LDESINFETANTE MARINE 5L | K20: 0.020833333
B21: DESINFETANTE PAIXAO 5L | H21: DESINFETANTE PAIXAO 5L | J21: =CONCATENATE($B$13,H21) -> AGUA SANITARIA 5LDESINFETANTE PAIXAO 5L | K21: 0.020833333
J22: =CONCATENATE($B$14,H13) -> ALVEJANTE S/ CLORO 3LAGUA SANITARIA 5L | K22: 0.020833333
J23: =CONCATENATE($B$14,H14) -> ALVEJANTE S/ CLORO 3LALVEJANTE S/ CLORO 3L | K23: 0.013888889
J24: =CONCATENATE($B$14,H15) -> ALVEJANTE S/ CLORO 3LDESINFETANTE CAMPOS LAVANDA 5L | K24: 0.020833333
J25: =CONCATENATE($B$14,H16) -> ALVEJANTE S/ CLORO 3LDESINFETANTE ENERGIA 5L | K25: 0.020833333
J26: =CONCATENATE($B$14,H17) -> ALVEJANTE S/ CLORO 3LDESINFETANTE FL. DE EUCALIPTO 5L | K26: 0.020833333
J27: =CONCATENATE($B$14,H18) -> ALVEJANTE S/ CLORO 3LDESINFETANTE HARMONIA NATURAL 5L | K27: 0.020833333
J28: =CONCATENATE($B$14,H19) -> ALVEJANTE S/ CLORO 3LDESINFETANTE JARDIM FLORIDO 5L | K28: 0.020833333
J29: =CONCATENATE($B$14,H20) -> ALVEJANTE S/ CLORO 3LDESINFETANTE MARINE 5L | K29: 0.020833333
J30: =CONCATENATE($B$14,H21) -> ALVEJANTE S/ CLORO 3LDESINFETANTE PAIXAO 5L | K30: 0.020833333
J31: =CONCATENATE($B$15,H13) -> DESINFETANTE CAMPOS LAVANDA 5LAGUA SANITARIA 5L | K31: 0.020833333
J32: =CONCATENATE($B$15,H14) -> DESINFETANTE CAMPOS LAVANDA 5LALVEJANTE S/ CLORO 3L | K32: 0.020833333
J33: =CONCATENATE($B$15,H15) -> DESINFETANTE CAMPOS LAVANDA 5LDESINFETANTE CAMPOS LAVANDA 5L | K33: 0.013888889
J34: =CONCATENATE($B$15,H16) -> DESINFETANTE CAMPOS LAVANDA 5LDESINFETANTE ENERGIA 5L | K34: 0.013888889
J35: =CONCATENATE($B$15,H17) -> DESINFETANTE CAMPOS LAVANDA 5LDESINFETANTE FL. DE EUCALIPTO 5L | K35: 0.013888889
J36: =CONCATENATE($B$15,H18) -> DESINFETANTE CAMPOS LAVANDA 5LDESINFETANTE HARMONIA NATURAL 5L | K36: 0.013888889
J37: =CONCATENATE($B$15,H19) -> DESINFETANTE CAMPOS LAVANDA 5LDESINFETANTE JARDIM FLORIDO 5L | K37: 0.013888889
J38: =CONCATENATE($B$15,H20) -> DESINFETANTE CAMPOS LAVANDA 5LDESINFETANTE MARINE 5L | K38: 0.013888889
J39: =CONCATENATE($B$15,H21) -> DESINFETANTE CAMPOS LAVANDA 5LDESINFETANTE PAIXAO 5L | K39: 0.013888889
J40: =CONCATENATE($B$16,H13) -> DESINFETANTE ENERGIA 5LAGUA SANITARIA 5L | K40: 0.020833333
J41: =CONCATENATE($B$16,H14) -> DESINFETANTE ENERGIA 5LALVEJANTE S/ CLORO 3L | K41: 0.020833333
J42: =CONCATENATE($B$16,H15) -> DESINFETANTE ENERGIA 5LDESINFETANTE CAMPOS LAVANDA 5L | K42: 0.013888889
...

Sheet Linha 3
A1: LINHA 03 | B1: AMACIANTE 2L | C1: DESINFETANTE 2L | D1: ELIMINADOR DE ODORES 2L | E1: LAVA ROUPAS 2L | F1: LIMP PERF 2L | I1: AMACIANTE AZUL FRESC. MANHA 2L | J1: AMACIANTE BRANCO PURA CARIC. 2L | K1: AMACIANTE ENERGIA 2L | L1: AMACIANTE ROSA JARD. FLORID 2L | M1: AMACIANTE ROXO MAGIA 2L | N1: AMACIANTE VERMELHO SEDUCAO 2L | O1: DESINFETANTE CAMPOS LAVANDA 2L | P1: DESINFETANTE ENERGIA 2L | Q1: DESINFETANTE FL.DE EUCALIPTO 2L | R1: DESINFETANTE HARMONIA NATURAL 2L | S1: DESINFETANTE JARDIM FLORIDO 2L | T1: DESINFETANTE MARINE 2L | U1: DESINFETANTE PAIXAO 2L | V1: ELIMINADOR DE ODORES FLORAL 2L | W1: ELIMINADOR DE ODORES FRESH 2L | X1: ELIMINADOR DE ODORES MARINE 2L | Y1: LAVA ROUPAS BABY 2L | Z1: LAVA ROUPAS GLICERINA 2L | AA1: LAVA ROUPAS MULTI ACAO 2L | AB1: LAVA ROUPAS TERNURA 2L | AC1: LIMP PERF DOCE ROMANCE 2L | AD1: LIMP PERF FRESCOR DA MANHA 2L | AE1: LIMP PERF MAGIA SEDUCAO 2L | AF1: LIMP PERF PRIMAVERA FLORIDA 2L
A2: AMACIANTE 2L | B2: 0.0069444444 | C2: 0.041666667 | D2: 0.041666667 | E2: 0.013888889 | F2: 0.041666667 | H2: AMACIANTE AZUL FRESC. MANHA 2L | I2: 0.0069444444 | J2: 0.0069444444 | K2: 0.0069444444 | L2: 0.0069444444 | M2: 0.0069444444 | N2: 0.0069444444 | O2: 0.041666667 | P2: 0.041666667 | Q2: 0.041666667 | R2: 0.041666667 | S2: 0.041666667 | T2: 0.041666667 | U2: 0.041666667 | V2: 0.041666667 | W2: 0.041666667 | X2: 0.041666667 | Y2: 0.013888889 | Z2: 0.013888889 | AA2: 0.013888889 | AB2: 0.013888889 | AC2: 0.041666667 | AD2: 0.041666667 | AE2: 0.041666667 | AF2: 0.041666667
A3: DESINFETANTE 2L | B3: 0.041666667 | C3: 0.0069444444 | D3: 0.041666667 | E3: 0.041666667 | F3: 0.041666667 | H3: AMACIANTE BRANCO PURA CARIC. 2L | I3: 0.0069444444 | J3: 0.0069444444 | K3: 0.0069444444 | L3: 0.0069444444 | M3: 0.0069444444 | N3: 0.0069444444 | O3: 0.041666667 | P3: 0.041666667 | Q3: 0.041666667 | R3: 0.041666667 | S3: 0.041666667 | T3: 0.041666667 | U3: 0.041666667 | V3: 0.041666667 | W3: 0.041666667 | X3: 0.041666667 | Y3: 0.013888889 | Z3: 0.013888889 | AA3: 0.013888889 | AB3: 0.013888889 | AC3: 0.041666667 | AD3: 0.041666667 | AE3: 0.041666667 | AF3: 0.041666667
A4: ELIMINADOR DE ODORES 2L | B4: 0.041666667 | C4: 0.041666667 | D4: 0.0069444444 | E4: 0.041666667 | F4: 0.013888889 | H4: AMACIANTE ENERGIA 2L | I4: 0.0069444444 | J4: 0.0069444444 | K4: 0.0069444444 | L4: 0.0069444444 | M4: 0.0069444444 | N4: 0.0069444444 | O4: 0.041666667 | P4: 0.041666667 | Q4: 0.041666667 | R4: 0.041666667 | S4: 0.041666667 | T4: 0.041666667 | U4: 0.041666667 | V4: 0.041666667 | W4: 0.041666667 | X4: 0.041666667 | Y4: 0.013888889 | Z4: 0.013888889 | AA4: 0.013888889 | AB4: 0.013888889 | AC4: 0.041666667 | AD4: 0.041666667 | AE4: 0.041666667 | AF4: 0.041666667
A5: LAVA ROUPAS 2L | B5: 0.013888889 | C5: 0.041666667 | D5: 0.041666667 | E5: 0.0069444444 | F5: 0.041666667 | H5: AMACIANTE ROSA JARD. FLORID 2L | I5: 0.0069444444 | J5: 0.0069444444 | K5: 0.0069444444 | L5: 0.0069444444 | M5: 0.0069444444 | N5: 0.0069444444 | O5: 0.041666667 | P5: 0.041666667 | Q5: 0.041666667 | R5: 0.041666667 | S5: 0.041666667 | T5: 0.041666667 | U5: 0.041666667 | V5: 0.041666667 | W5: 0.041666667 | X5: 0.041666667 | Y5: 0.013888889 | Z5: 0.013888889 | AA5: 0.013888889 | AB5: 0.013888889 | AC5: 0.041666667 | AD5: 0.041666667 | AE5: 0.041666667 | AF5: 0.041666667
A6: LIMP PERF 2L | B6: 0.041666667 | C6: 0.041666667 | D6: 0.013888889 | E6: 0.041666667 | F6: 0.0069444444 | H6: AMACIANTE ROXO MAGIA 2L | I6: 0.0069444444 | J6: 0.0069444444 | K6: 0.0069444444 | L6: 0.0069444444 | M6: 0.0069444444 | N6: 0.0069444444 | O6: 0.041666667 | P6: 0.041666667 | Q6: 0.041666667 | R6: 0.041666667 | S6: 0.041666667 | T6: 0.041666667 | U6: 0.041666667 | V6: 0.041666667 | W6: 0.041666667 | X6: 0.041666667 | Y6: 0.013888889 | Z6: 0.013888889 | AA6: 0.013888889 | AB6: 0.013888889 | AC6: 0.041666667 | AD6: 0.041666667 | AE6: 0.041666667 | AF6: 0.041666667
H7: AMACIANTE VERMELHO SEDUCAO 2L | I7: 0.0069444444 | J7: 0.0069444444 | K7: 0.0069444444 | L7: 0.0069444444 | M7: 0.0069444444 | N7: 0.0069444444 | O7: 0.041666667 | P7: 0.041666667 | Q7: 0.041666667 | R7: 0.041666667 | S7: 0.041666667 | T7: 0.041666667 | U7: 0.041666667 | V7: 0.041666667 | W7: 0.041666667 | X7: 0.041666667 | Y7: 0.013888889 | Z7: 0.013888889 | AA7: 0.013888889 | AB7: 0.013888889 | AC7: 0.041666667 | AD7: 0.041666667 | AE7: 0.041666667 | AF7: 0.041666667
H8: DESINFETANTE CAMPOS LAVANDA 2L | I8: 0.041666667 | J8: 0.041666667 | K8: 0.041666667 | L8: 0.041666667 | M8: 0.041666667 | N8: 0.041666667 | O8: 0.0069444444 | P8: 0.0069444444 | Q8: 0.0069444444 | R8: 0.0069444444 | S8: 0.0069444444 | T8: 0.0069444444 | U8: 0.0069444444 | V8: 0.041666667 | W8: 0.041666667 | X8: 0.041666667 | Y8: 0.041666667 | Z8: 0.041666667 | AA8: 0.041666667 | AB8: 0.041666667 | AC8: 0.041666667 | AD8: 0.041666667 | AE8: 0.041666667 | AF8: 0.041666667
H9: DESINFETANTE ENERGIA 2L | I9: 0.041666667 | J9: 0.041666667 | K9: 0.041666667 | L9: 0.041666667 | M9: 0.041666667 | N9: 0.041666667 | O9: 0.0069444444 | P9: 0.0069444444 | Q9: 0.0069444444 | R9: 0.0069444444 | S9: 0.0069444444 | T9: 0.0069444444 | U9: 0.0069444444 | V9: 0.041666667 | W9: 0.041666667 | X9: 0.041666667 | Y9: 0.041666667 | Z9: 0.041666667 | AA9: 0.041666667 | AB9: 0.041666667 | AC9: 0.041666667 | AD9: 0.041666667 | AE9: 0.041666667 | AF9: 0.041666667
H10: DESINFETANTE FL.DE EUCALIPTO 2L | I10: 0.041666667 | J10: 0.041666667 | K10: 0.041666667 | L10: 0.041666667 | M10: 0.041666667 | N10: 0.041666667 | O10: 0.0069444444 | P10: 0.0069444444 | Q10: 0.0069444444 | R10: 0.0069444444 | S10: 0.0069444444 | T10: 0.0069444444 | U10: 0.0069444444 | V10: 0.041666667 | W10: 0.041666667 | X10: 0.041666667 | Y10: 0.041666667 | Z10: 0.041666667 | AA10: 0.041666667 | AB10: 0.041666667 | AC10: 0.041666667 | AD10: 0.041666667 | AE10: 0.041666667 | AF10: 0.041666667
H11: DESINFETANTE HARMONIA NATURAL 2L | I11: 0.041666667 | J11: 0.041666667 | K11: 0.041666667 | L11: 0.041666667 | M11: 0.041666667 | N11: 0.041666667 | O11: 0.0069444444 | P11: 0.0069444444 | Q11: 0.0069444444 | R11: 0.0069444444 | S11: 0.0069444444 | T11: 0.0069444444 | U11: 0.0069444444 | V11: 0.041666667 | W11: 0.041666667 | X11: 0.041666667 | Y11: 0.041666667 | Z11: 0.041666667 | AA11: 0.041666667 | AB11: 0.041666667 | AC11: 0.041666667 | AD11: 0.041666667 | AE11: 0.041666667 | AF11: 0.041666667
H12: DESINFETANTE JARDIM FLORIDO 2L | I12: 0.041666667 | J12: 0.041666667 | K12: 0.041666667 | L12: 0.041666667 | M12: 0.041666667 | N12: 0.041666667 | O12: 0.0069444444 | P12: 0.0069444444 | Q12: 0.0069444444 | R12: 0.0069444444 | S12: 0.0069444444 | T12: 0.0069444444 | U12: 0.0069444444 | V12: 0.041666667 | W12: 0.041666667 | X12: 0.041666667 | Y12: 0.041666667 | Z12: 0.041666667 | AA12: 0.041666667 | AB12: 0.041666667 | AC12: 0.041666667 | AD12: 0.041666667 | AE12: 0.041666667 | AF12: 0.041666667
H13: DESINFETANTE MARINE 2L | I13: 0.041666667 | J13: 0.041666667 | K13: 0.041666667 | L13: 0.041666667 | M13: 0.041666667 | N13: 0.041666667 | O13: 0.0069444444 | P13: 0.0069444444 | Q13: 0.0069444444 | R13: 0.0069444444 | S13: 0.0069444444 | T13: 0.0069444444 | U13: 0.0069444444 | V13: 0.041666667 | W13: 0.041666667 | X13: 0.041666667 | Y13: 0.041666667 | Z13: 0.041666667 | AA13: 0.041666667 | AB13: 0.041666667 | AC13: 0.041666667 | AD13: 0.041666667 | AE13: 0.041666667 | AF13: 0.041666667
H14: DESINFETANTE PAIXAO 2L | I14: 0.041666667 | J14: 0.041666667 | K14: 0.041666667 | L14: 0.041666667 | M14: 0.041666667 | N14: 0.041666667 | O14: 0.0069444444 | P14: 0.0069444444 | Q14: 0.0069444444 | R14: 0.0069444444 | S14: 0.0069444444 | T14: 0.0069444444 | U14: 0.0069444444 | V14: 0.041666667 | W14: 0.041666667 | X14: 0.041666667 | Y14: 0.041666667 | Z14: 0.041666667 | AA14: 0.041666667 | AB14: 0.041666667 | AC14: 0.041666667 | AD14: 0.041666667 | AE14: 0.041666667 | AF14: 0.041666667
H15: ELIMINADOR DE ODORES FLORAL 2L | I15: 0.041666667 | J15: 0.041666667 | K15: 0.041666667 | L15: 0.041666667 | M15: 0.041666667 | N15: 0.041666667 | O15: 0.041666667 | P15: 0.041666667 | Q15: 0.041666667 | R15: 0.041666667 | S15: 0.041666667 | T15: 0.041666667 | U15: 0.041666667 | V15: 0.0069444444 | W15: 0.0069444444 | X15: 0.0069444444 | Y15: 0.041666667 | Z15: 0.041666667 | AA15: 0.041666667 | AB15: 0.041666667 | AC15: 0.013888889 | AD15: 0.013888889 | AE15: 0.013888889 | AF15: 0.013888889
H16: ELIMINADOR DE ODORES FRESH 2L | I16: 0.041666667 | J16: 0.041666667 | K16: 0.041666667 | L16: 0.041666667 | M16: 0.041666667 | N16: 0.041666667 | O16: 0.041666667 | P16: 0.041666667 | Q16: 0.041666667 | R16: 0.041666667 | S16: 0.041666667 | T16: 0.041666667 | U16: 0.041666667 | V16: 0.0069444444 | W16: 0.0069444444 | X16: 0.0069444444 | Y16: 0.041666667 | Z16: 0.041666667 | AA16: 0.041666667 | AB16: 0.041666667 | AC16: 0.013888889 | AD16: 0.013888889 | AE16: 0.013888889 | AF16: 0.013888889
H17: ELIMINADOR DE ODORES MARINE 2L | I17: 0.041666667 | J17: 0.041666667 | K17: 0.041666667 | L17: 0.041666667 | M17: 0.041666667 | N17: 0.041666667 | O17: 0.041666667 | P17: 0.041666667 | Q17: 0.041666667 | R17: 0.041666667 | S17: 0.041666667 | T17: 0.041666667 | U17: 0.041666667 | V17: 0.0069444444 | W17: 0.0069444444 | X17: 0.0069444444 | Y17: 0.041666667 | Z17: 0.041666667 | AA17: 0.041666667 | AB17: 0.041666667 | AC17: 0.013888889 | AD17: 0.013888889 | AE17: 0.013888889 | AF17: 0.013888889
H18: LAVA ROUPAS BABY 2L | I18: 0.013888889 | J18: 0.013888889 | K18: 0.013888889 | L18: 0.013888889 | M18: 0.013888889 | N18: 0.013888889 | O18: 0.041666667 | P18: 0.041666667 | Q18: 0.041666667 | R18: 0.041666667 | S18: 0.041666667 | T18: 0.041666667 | U18: 0.041666667 | V18: 0.041666667 | W18: 0.041666667 | X18: 0.041666667 | Y18: 0.0069444444 | Z18: 0.0069444444 | AA18: 0.0069444444 | AB18: 0.0069444444 | AC18: 0.041666667 | AD18: 0.041666667 | AE18: 0.041666667 | AF18: 0.041666667
... H25: LIMP PERF PRIMAVERA FLORIDA 2L | I25: 0.041666667 | J25: 0.041666667 | K25: 0.041666667 | L25: 0.041666667 | M25: 0.041666667 | N25: 0.041666667 | O25: 0.041666667 | P25: 0.041666667 | Q25: 0.041666667 | R25: 0.041666667 | S25: 0.041666667 | T25: 0.041666667 | U25: 0.041666667 | V25: 0.013888889 | W25: 0.013888889 | X25: 0.013888889 | Y25: 0.041666667 | Z25: 0.041666667 | AA25: 0.041666667 | AB25: 0.041666667 | AC25: 0.0069444444 | AD25: 0.0069444444 | AE25: 0.0069444444 | AF25: 0.0069444444
A28: AMACIANTE AZUL FRESC. MANHA 2L | H28: AMACIANTE AZUL FRESC. MANHA 2L | J28: =CONCATENATE($A$28,$H28) -> AMACIANTE AZUL FRESC. MANHA 2LAMACIANTE AZUL FRESC. MANHA 2L | K28: 0.0069444444
A29: AMACIANTE BRANCO PURA CARIC. 2L | H29: AMACIANTE BRANCO PURA CARIC. 2L | J29: =CONCATENATE($A$28,H29) -> AMACIANTE AZUL FRESC. MANHA 2LAMACIANTE BRANCO PURA CARIC. 2L | K29: 0.0069444444
A30: AMACIANTE ENERGIA 2L | H30: AMACIANTE ENERGIA 2L | J30: =CONCATENATE($A$28,H30) -> AMACIANTE AZUL FRESC. MANHA 2LAMACIANTE ENERGIA 2L | K30: 0.0069444444
A31: AMACIANTE ROSA JARD. FLORID 2L | H31: AMACIANTE ROSA JARD. FLORID 2L | J31: =CONCATENATE($A$28,H31) -> AMACIANTE AZUL FRESC. MANHA 2LAMACIANTE ROSA JARD. FLORID 2L | K31: 0.0069444444
A32: AMACIANTE ROXO MAGIA 2L | H32: AMACIANTE ROXO MAGIA 2L | J32: =CONCATENATE($A$28,H32) -> AMACIANTE AZUL FRESC. MANHA 2LAMACIANTE ROXO MAGIA 2L | K32: 0.0069444444
A33: AMACIANTE VERMELHO SEDUCAO 2L | H33: AMACIANTE VERMELHO SEDUCAO 2L | J33: =CONCATENATE($A$28,H33) -> AMACIANTE AZUL FRESC. MANHA 2LAMACIANTE VERMELHO SEDUCAO 2L | K33: 0.0069444444
A34: DESINFETANTE CAMPOS LAVANDA 2L | H34: DESINFETANTE CAMPOS LAVANDA 2L | J34: =CONCATENATE($A$28,H34) -> AMACIANTE AZUL FRESC. MANHA 2LDESINFETANTE CAMPOS LAVANDA 2L | K34: 0.041666667
A35: DESINFETANTE ENERGIA 2L | H35: DESINFETANTE ENERGIA 2L | J35: =CONCATENATE($A$28,H35) -> AMACIANTE AZUL FRESC. MANHA 2LDESINFETANTE ENERGIA 2L | K35: 0.041666667
A36: DESINFETANTE FL.DE EUCALIPTO 2L | H36: DESINFETANTE FL.DE EUCALIPTO 2L | J36: =CONCATENATE($A$28,H36) -> AMACIANTE AZUL FRESC. MANHA 2LDESINFETANTE FL.DE EUCALIPTO 2L | K36: 0.041666667
A37: DESINFETANTE HARMONIA NATURAL 2L | H37: DESINFETANTE HARMONIA NATURAL 2L | J37: =CONCATENATE($A$28,H37) -> AMACIANTE AZUL FRESC. MANHA 2LDESINFETANTE HARMONIA NATURAL 2L | K37: 0.041666667
A38: DESINFETANTE JARDIM FLORIDO 2L | H38: DESINFETANTE JARDIM FLORIDO 2L | J38: =CONCATENATE($A$28,H38) -> AMACIANTE AZUL FRESC. MANHA 2LDESINFETANTE JARDIM FLORIDO 2L | K38: 0.041666667
A39: DESINFETANTE MARINE 2L | H39: DESINFETANTE MARINE 2L | J39: =CONCATENATE($A$28,H39) -> AMACIANTE AZUL FRESC. MANHA 2LDESINFETANTE MARINE 2L | K39: 0.041666667
A40: DESINFETANTE PAIXAO 2L | H40: DESINFETANTE PAIXAO 2L | J40: =CONCATENATE($A$28,H40) -> AMACIANTE AZUL FRESC. MANHA 2LDESINFETANTE PAIXAO 2L | K40: 0.041666667
... A51: LIMP PERF PRIMAVERA FLORIDA 2L | H51: LIMP PERF PRIMAVERA FLORIDA 2L | J51: =CONCATENATE($A$28,H51) -> AMACIANTE AZUL FRESC. MANHA 2LLIMP PERF PRIMAVERA FLORIDA 2L | K51: 0.041666667
J52: =CONCATENATE($A$29,$H28) -> AMACIANTE BRANCO PURA CARIC. 2LAMACIANTE AZUL FRESC. MANHA 2L | K52: 0.0069444444
J53: =CONCATENATE($A$29,$H29) -> AMACIANTE BRANCO PURA CARIC. 2LAMACIANTE BRANCO PURA CARIC. 2L | K53: 0.0069444444
J54: =CONCATENATE($A$29,$H30) -> AMACIANTE BRANCO PURA CARIC. 2LAMACIANTE ENERGIA 2L | K54: 0.0069444444
J55: =CONCATENATE($A$29,$H31) -> AMACIANTE BRANCO PURA CARIC. 2LAMACIANTE ROSA JARD. FLORID 2L | K55: 0.0069444444
J56: =CONCATENATE($A$29,$H32) -> AMACIANTE BRANCO PURA CARIC. 2LAMACIANTE ROXO MAGIA 2L | K56: 0.0069444444
J57: =CONCATENATE($A$29,$H33) -> AMACIANTE BRANCO PURA CARIC. 2LAMACIANTE VERMELHO SEDUCAO 2L | K57: 0.0069444444
J58: =CONCATENATE($A$29,$H34) -> AMACIANTE BRANCO PURA CARIC. 2LDESINFETANTE CAMPOS LAVANDA 2L | K58: 0.041666667
...

Sheet Linha 4
B3: =CONCATENATE(B22,C21) -> DESINFETANTE 500MLDESINFETANTE 500ML | C3: 0.0069444444
B4: =CONCATENATE(B22,D21) -> DESINFETANTE 500MLDETERGENTE 1L | C4: 0.055555556
B5: =CONCATENATE(B22,E21) -> DESINFETANTE 500MLDETERGENTE 500ML | C5: 0.034722222
B6: =CONCATENATE(B23,C21) -> DETERGENTE 1LDESINFETANTE 500ML | C6: 0.055555556
B7: =CONCATENATE(B23,D21) -> DETERGENTE 1LDETERGENTE 1L | C7: 0.0069444444
B8: =CONCATENATE(B23,E21) -> DETERGENTE 1LDETERGENTE 500ML | C8: 0.055555556
B9: =CONCATENATE(B24,C21) -> DETERGENTE 500MLDESINFETANTE 500ML | C9: 0.034722222
B10: =CONCATENATE(B24,D21) -> DETERGENTE 500MLDETERGENTE 1L | C10: 0.055555556
B11: =CONCATENATE(B24,E21) -> DETERGENTE 500MLDETERGENTE 500ML | C11: 0.0069444444
B21: LINHA 04 | C21: DESINFETANTE 500ML | D21: DETERGENTE 1L | E21: DETERGENTE 500ML | J21: DESINFETANTE CAMPOS LAVANDA 500ML | K21: DESINFETANTE FL. DE EUCALIPTO 500ML | L21: DESINFETANTE JARDIM FLORIDO 500ML | M21: DESINFETANTE PAIXAO 500ML | N21: DETERGENTE CLEAR 1L | O21: DETERGENTE CLEAR 500ML (NATURAL) | P21: DETERGENTE COCO 500ML | Q21: DETERGENTE LIMAO 1L | R21: DETERGENTE LIMAO 500ML | S21: DETERGENTE MAÇA 1L | T21: DETERGENTE MACA 500ML | U21: DETERGENTE NEUTRO 1L | V21: DETERGENTE NEUTRO 500ML
B22: DESINFETANTE 500ML | C22: 0.0069444444 | D22: 0.055555556 | E22: 0.034722222 | I22: DESINFETANTE CAMPOS LAVANDA 500ML | J22: 0.0069444444 | K22: 0.0069444444 | L22: 0.0069444444 | M22: 0.0069444444 | N22: 0.055555556 | O22: 0.034722222 | P22: 0.034722222 | Q22: 0.055555556 | R22: 0.034722222 | S22: 0.055555556 | T22: 0.034722222 | U22: 0.055555556 | V22: 0.034722222
B23: DETERGENTE 1L | C23: 0.055555556 | D23: 0.0069444444 | E23: 0.055555556 | I23: DESINFETANTE FL. DE EUCALIPTO 500ML | J23: 0.0069444444 | K23: 0.0069444444 | L23: 0.0069444444 | M23: 0.0069444444 | N23: 0.055555556 | O23: 0.034722222 | P23: 0.034722222 | Q23: 0.055555556 | R23: 0.034722222 | S23: 0.055555556 | T23: 0.034722222 | U23: 0.055555556 | V23: 0.034722222
B24: DETERGENTE 500ML | C24: 0.034722222 | D24: 0.055555556 | E24: 0.0069444444 | I24: DESINFETANTE JARDIM FLORIDO 500ML | J24: 0.0069444444 | K24: 0.0069444444 | L24: 0.0069444444 | M24: 0.0069444444 | N24: 0.055555556 | O24: 0.034722222 | P24: 0.034722222 | Q24: 0.055555556 | R24: 0.034722222 | S24: 0.055555556 | T24: 0.034722222 | U24: 0.055555556 | V24: 0.034722222
I25: DESINFETANTE PAIXAO 500ML | J25: 0.0069444444 | K25: 0.0069444444 | L25: 0.0069444444 | M25: 0.0069444444 | N25: 0.055555556 | O25: 0.034722222 | P25: 0.034722222 | Q25: 0.055555556 | R25: 0.034722222 | S25: 0.055555556 | T25: 0.034722222 | U25: 0.055555556 | V25: 0.034722222
I26: DETERGENTE CLEAR 1L | J26: 0.055555556 | K26: 0.055555556 | L26: 0.055555556 | M26: 0.055555556 | N26: 0.0069444444 | O26: 0.055555556 | P26: 0.055555556 | Q26: 0.0069444444 | R26: 0.055555556 | S26: 0.0069444444 | T26: 0.055555556 | U26: 0.0069444444 | V26: 0.055555556
I27: DETERGENTE CLEAR 500ML (NATURAL) | J27: 0.034722222 | K27: 0.034722222 | L27: 0.034722222 | M27: 0.034722222 | N27: 0.055555556 | O27: 0.0069444444 | P27: 0.0069444444 | Q27: 0.055555556 | R27: 0.0069444444 | S27: 0.055555556 | T27: 0.0069444444 | U27: 0.055555556 | V27: 0.0069444444
I28: DETERGENTE COCO 500ML | J28: 0.034722222 | K28: 0.034722222 | L28: 0.034722222 | M28: 0.034722222 | N28: 0.055555556 | O28: 0.0069444444 | P28: 0.0069444444 | Q28: 0.055555556 | R28: 0.0069444444 | S28: 0.055555556 | T28: 0.0069444444 | U28: 0.055555556 | V28: 0.0069444444
I29: DETERGENTE LIMAO 1L | J29: 0.055555556 | K29: 0.055555556 | L29: 0.055555556 | M29: 0.055555556 | N29: 0.0069444444 | O29: 0.055555556 | P29: 0.055555556 | Q29: 0.0069444444 | R29: 0.055555556 | S29: 0.0069444444 | T29: 0.055555556 | U29: 0.0069444444 | V29: 0.055555556
I30: DETERGENTE LIMAO 500ML | J30: 0.034722222 | K30: 0.034722222 | L30: 0.034722222 | M30: 0.034722222 | N30: 0.055555556 | O30: 0.0069444444 | P30: 0.0069444444 | Q30: 0.055555556 | R30: 0.0069444444 | S30: 0.055555556 | T30: 0.0069444444 | U30: 0.055555556 | V30: 0.0069444444
I31: DETERGENTE MAÇA 1L | J31: 0.055555556 | K31: 0.055555556 | L31: 0.055555556 | M31: 0.055555556 | N31: 0.0069444444 | O31: 0.055555556 | P31: 0.055555556 | Q31: 0.0069444444 | R31: 0.055555556 | S31: 0.0069444444 | T31: 0.055555556 | U31: 0.0069444444 | V31: 0.055555556
I32: DETERGENTE MACA 500ML | J32: 0.034722222 | K32: 0.034722222 | L32: 0.034722222 | M32: 0.034722222 | N32: 0.055555556 | O32: 0.0069444444 | P32: 0.0069444444 | Q32: 0.055555556 | R32: 0.0069444444 | S32: 0.055555556 | T32: 0.0069444444 | U32: 0.055555556 | V32: 0.0069444444
I33: DETERGENTE NEUTRO 1L | J33: 0.055555556 | K33: 0.055555556 | L33: 0.055555556 | M33: 0.055555556 | N33: 0.0069444444 | O33: 0.055555556 | P33: 0.055555556 | Q33: 0.0069444444 | R33: 0.055555556 | S33: 0.0069444444 | T33: 0.055555556 | U33: 0.0069444444 | V33: 0.055555556
I34: DETERGENTE NEUTRO 500ML | J34: 0.034722222 | K34: 0.034722222 | L34: 0.034722222 | M34: 0.034722222 | N34: 0.055555556 | O34: 0.0069444444 | P34: 0.0069444444 | Q34: 0.055555556 | R34: 0.0069444444 | S34: 0.055555556 | T34: 0.0069444444 | U34: 0.055555556 | V34: 0.0069444444
B39: DESINFETANTE CAMPOS LAVANDA 500ML | I39: DESINFETANTE CAMPOS LAVANDA 500ML | K39: =CONCATENATE($B$39,I39) -> DESINFETANTE CAMPOS LAVANDA 500MLDESINFETANTE CAMPOS LAVANDA 500ML | L39: 0.0069444444
B40: DESINFETANTE FL. DE EUCALIPTO 500ML | I40: DESINFETANTE FL. DE EUCALIPTO 500ML | K40: =CONCATENATE($B$39,I40) -> DESINFETANTE CAMPOS LAVANDA 500MLDESINFETANTE FL. DE EUCALIPTO 500ML | L40: 0.0069444444
B41: DESINFETANTE JARDIM FLORIDO 500ML | I41: DESINFETANTE JARDIM FLORIDO 500ML | K41: =CONCATENATE($B$39,I41) -> DESINFETANTE CAMPOS LAVANDA 500MLDESINFETANTE JARDIM FLORIDO 500ML | L41: 0.0069444444
B42: DESINFETANTE PAIXAO 500ML | I42: DESINFETANTE PAIXAO 500ML | K42: =CONCATENATE($B$39,I42) -> DESINFETANTE CAMPOS LAVANDA 500MLDESINFETANTE PAIXAO 500ML | L42: 0.0069444444
B43: DETERGENTE CLEAR 1L | I43: DETERGENTE CLEAR 1L | K43: =CONCATENATE($B$39,I43) -> DESINFETANTE CAMPOS LAVANDA 500MLDETERGENTE CLEAR 1L | L43: 0.055555556
B44: DETERGENTE CLEAR 500ML (NATURAL) | I44: DETERGENTE CLEAR 500ML (NATURAL) | K44: =CONCATENATE($B$39,I44) -> DESINFETANTE CAMPOS LAVANDA 500MLDETERGENTE CLEAR 500ML (NATURAL) | L44: 0.034722222
B45: DETERGENTE COCO 500ML | I45: DETERGENTE COCO 500ML | K45: =CONCATENATE($B$39,I45) -> DESINFETANTE CAMPOS LAVANDA 500MLDETERGENTE COCO 500ML | L45: 0.034722222
B46: DETERGENTE LIMAO 1L | I46: DETERGENTE LIMAO 1L | K46: =CONCATENATE($B$39,I46) -> DESINFETANTE CAMPOS LAVANDA 500MLDETERGENTE LIMAO 1L | L46: 0.055555556
B47: DETERGENTE LIMAO 500ML | I47: DETERGENTE LIMAO 500ML | K47: =CONCATENATE($B$39,I47) -> DESINFETANTE CAMPOS LAVANDA 500MLDETERGENTE LIMAO 500ML | L47: 0.034722222
B48: DETERGENTE MAÇA 1L | I48: DETERGENTE MAÇA 1L | K48: =CONCATENATE($B$39,I48) -> DESINFETANTE CAMPOS LAVANDA 500MLDETERGENTE MAÇA 1L | L48: 0.055555556
B49: DETERGENTE MACA 500ML | I49: DETERGENTE MACA 500ML | K49: =CONCATENATE($B$39,I49) -> DESINFETANTE CAMPOS LAVANDA 500MLDETERGENTE MACA 500ML | L49: 0.034722222
B50: DETERGENTE NEUTRO 1L | I50: DETERGENTE NEUTRO 1L | K50: =CONCATENATE($B$39,I50) -> DESINFETANTE CAMPOS LAVANDA 500MLDETERGENTE NEUTRO 1L | L50: 0.055555556
B51: DETERGENTE NEUTRO 500ML | I51: DETERGENTE NEUTRO 500ML | K51: =CONCATENATE($B$39,I51) -> DESINFETANTE CAMPOS LAVANDA 500MLDETERGENTE NEUTRO 500ML | L51: 0.034722222
K52: =CONCATENATE($B$40,I39) -> DESINFETANTE FL. DE EUCALIPTO 500MLDESINFETANTE CAMPOS LAVANDA 500ML | L52: 0.0069444444
K53: =CONCATENATE($B$40,I40) -> DESINFETANTE FL. DE EUCALIPTO 500MLDESINFETANTE FL. DE EUCALIPTO 500ML | L53: 0.0069444444
K54: =CONCATENATE($B$40,I41) -> DESINFETANTE FL. DE EUCALIPTO 500MLDESINFETANTE JARDIM FLORIDO 500ML | L54: 0.0069444444
K55: =CONCATENATE($B$40,I42) -> DESINFETANTE FL. DE EUCALIPTO 500MLDESINFETANTE PAIXAO 500ML | L55: 0.0069444444
...

Sheet Linha 5
A1: LINHA 05 | B1: ALVEJANTE S/ CLORO 5L | C1: AMAC. CONC. 3L | D1: AMACIANTE 5L | E1: DETERGENTE 5L | F1: LAVA ROUPAS 3L | G1: LAVA ROUPAS 5L | J1: ALVEJANTE S/ CLORO 5L | K1: AMAC. CONC. BRANCO TERNURA 3L | L1: AMAC. CONC. ROSA ROMANCE 3L | M1: AMAC. CONC. VERMELHO SEDUCAO 3L | N1: AMACIANTE AZUL FRESC. MANHA 5L | O1: AMACIANTE BRANCO PURA CARIC. 5L | P1: AMACIANTE ENERGIA 5L | Q1: AMACIANTE ROSA JARD. FLORID 5L | R1: AMACIANTE ROXO MAGIA 5L | S1: AMACIANTE VERMELHO SEDUCAO 5L | T1: DETERGENTE CLEAR 5L | U1: DETERGENTE LIMAO 5L | V1: DETERGENTE MAÇA 5L | W1: DETERGENTE NEUTRO 5L | X1: LAVA ROUPAS COCO 3L | Y1: LAVA ROUPAS GLICERINA 3L | Z1: LAVA ROUPAS MULTI ACAO 3L | AA1: LAVA ROUPAS MULTI ACAO 5L | AB1: LAVA ROUPAS SPORTS 3L | AC1: LAVA ROUPAS TERNURA 3L | AD1: LAVA ROUPAS TERNURA 5L
A2: ALVEJANTE S/ CLORO 5L | B2: 0.0069444444 | C2: 0.052083333 | D2: 0.013888889 | E2: 0.013888889 | F2: 0.052083333 | G2: 0.013888889 | I2: ALVEJANTE S/ CLORO 5L | J2: 0.0069444444 | K2: 0.052083333 | L2: 0.052083333 | M2: 0.052083333 | N2: 0.013888889 | O2: 0.013888889 | P2: 0.013888889 | Q2: 0.013888889 | R2: 0.013888889 | S2: 0.013888889 | T2: 0.013888889 | U2: 0.013888889 | V2: 0.013888889 | W2: 0.013888889 | X2: 0.052083333 | Y2: 0.052083333 | Z2: 0.052083333 | AA2: 0.013888889 | AB2: 0.052083333 | AC2: 0.052083333 | AD2: 0.013888889
A3: AMAC. CONC. 3L | B3: 0.052083333 | C3: 0.0069444444 | D3: 0.052083333 | E3: 0.052083333 | F3: 0.013888889 | G3: 0.052083333 | I3: AMAC. CONC. BRANCO TERNURA 3L | J3: 0.052083333 | K3: 0.0069444444 | L3: 0.0069444444 | M3: 0.0069444444 | N3: 0.052083333 | O3: 0.052083333 | P3: 0.052083333 | Q3: 0.052083333 | R3: 0.052083333 | S3: 0.052083333 | T3: 0.052083333 | U3: 0.052083333 | V3: 0.052083333 | W3: 0.052083333 | X3: 0.013888889 | Y3: 0.013888889 | Z3: 0.013888889 | AA3: 0.052083333 | AB3: 0.013888889 | AC3: 0.013888889 | AD3: 0.052083333
A4: AMACIANTE 5L | B4: 0.013888889 | C4: 0.052083333 | D4: 0.0069444444 | E4: 0.013888889 | F4: 0.052083333 | G4: 0.013888889 | I4: AMAC. CONC. ROSA ROMANCE 3L | J4: 0.052083333 | K4: 0.0069444444 | L4: 0.0069444444 | M4: 0.0069444444 | N4: 0.052083333 | O4: 0.052083333 | P4: 0.052083333 | Q4: 0.052083333 | R4: 0.052083333 | S4: 0.052083333 | T4: 0.052083333 | U4: 0.052083333 | V4: 0.052083333 | W4: 0.052083333 | X4: 0.013888889 | Y4: 0.013888889 | Z4: 0.013888889 | AA4: 0.052083333 | AB4: 0.013888889 | AC4: 0.013888889 | AD4: 0.052083333
A5: DETERGENTE 5L | B5: 0.013888889 | C5: 0.052083333 | D5: 0.013888889 | E5: 0.0069444444 | F5: 0.052083333 | G5: 0.013888889 | I5: AMAC. CONC. VERMELHO SEDUCAO 3L | J5: 0.052083333 | K5: 0.0069444444 | L5: 0.0069444444 | M5: 0.0069444444 | N5: 0.052083333 | O5: 0.052083333 | P5: 0.052083333 | Q5: 0.052083333 | R5: 0.052083333 | S5: 0.052083333 | T5: 0.052083333 | U5: 0.052083333 | V5: 0.052083333 | W5: 0.052083333 | X5: 0.013888889 | Y5: 0.013888889 | Z5: 0.013888889 | AA5: 0.052083333 | AB5: 0.013888889 | AC5: 0.013888889 | AD5: 0.052083333
A6: LAVA ROUPAS 3L | B6: 0.052083333 | C6: 0.013888889 | D6: 0.052083333 | E6: 0.052083333 | F6: 0.0069444444 | G6: 0.052083333 | I6: AMACIANTE AZUL FRESC. MANHA 5L | J6: 0.013888889 | K6: 0.052083333 | L6: 0.052083333 | M6: 0.052083333 | N6: 0.0069444444 | O6: 0.0069444444 | P6: 0.0069444444 | Q6: 0.0069444444 | R6: 0.0069444444 | S6: 0.0069444444 | T6: 0.013888889 | U6: 0.013888889 | V6: 0.013888889 | W6: 0.013888889 | X6: 0.052083333 | Y6: 0.052083333 | Z6: 0.052083333 | AA6: 0.013888889 | AB6: 0.052083333 | AC6: 0.052083333 | AD6: 0.013888889
A7: LAVA ROUPAS 5L | B7: 0.013888889 | C7: 0.052083333 | D7: 0.013888889 | E7: 0.013888889 | F7: 0.052083333 | G7: 0.0069444444 | I7: AMACIANTE BRANCO PURA CARIC. 5L | J7: 0.013888889 | K7: 0.052083333 | L7: 0.052083333 | M7: 0.052083333 | N7: 0.0069444444 | O7: 0.0069444444 | P7: 0.0069444444 | Q7: 0.0069444444 | R7: 0.0069444444 | S7: 0.0069444444 | T7: 0.013888889 | U7: 0.013888889 | V7: 0.013888889 | W7: 0.013888889 | X7: 0.052083333 | Y7: 0.052083333 | Z7: 0.052083333 | AA7: 0.013888889 | AB7: 0.052083333 | AC7: 0.052083333 | AD7: 0.013888889
I8: AMACIANTE ENERGIA 5L | J8: 0.013888889 | K8: 0.052083333 | L8: 0.052083333 | M8: 0.052083333 | N8: 0.0069444444 | O8: 0.0069444444 | P8: 0.0069444444 | Q8: 0.0069444444 | R8: 0.0069444444 | S8: 0.0069444444 | T8: 0.013888889 | U8: 0.013888889 | V8: 0.013888889 | W8: 0.013888889 | X8: 0.052083333 | Y8: 0.052083333 | Z8: 0.052083333 | AA8: 0.013888889 | AB8: 0.052083333 | AC8: 0.052083333 | AD8: 0.013888889
I9: AMACIANTE ROSA JARD. FLORID 5L | J9: 0.013888889 | K9: 0.052083333 | L9: 0.052083333 | M9: 0.052083333 | N9: 0.0069444444 | O9: 0.0069444444 | P9: 0.0069444444 | Q9: 0.0069444444 | R9: 0.0069444444 | S9: 0.0069444444 | T9: 0.013888889 | U9: 0.013888889 | V9: 0.013888889 | W9: 0.013888889 | X9: 0.052083333 | Y9: 0.052083333 | Z9: 0.052083333 | AA9: 0.013888889 | AB9: 0.052083333 | AC9: 0.052083333 | AD9: 0.013888889
I10: AMACIANTE ROXO MAGIA 5L | J10: 0.013888889 | K10: 0.052083333 | L10: 0.052083333 | M10: 0.052083333 | N10: 0.0069444444 | O10: 0.0069444444 | P10: 0.0069444444 | Q10: 0.0069444444 | R10: 0.0069444444 | S10: 0.0069444444 | T10: 0.013888889 | U10: 0.013888889 | V10: 0.013888889 | W10: 0.013888889 | X10: 0.052083333 | Y10: 0.052083333 | Z10: 0.052083333 | AA10: 0.013888889 | AB10: 0.052083333 | AC10: 0.052083333 | AD10: 0.013888889
I11: AMACIANTE VERMELHO SEDUCAO 5L | J11: 0.013888889 | K11: 0.052083333 | L11: 0.052083333 | M11: 0.052083333 | N11: 0.0069444444 | O11: 0.0069444444 | P11: 0.0069444444 | Q11: 0.0069444444 | R11: 0.0069444444 | S11: 0.0069444444 | T11: 0.013888889 | U11: 0.013888889 | V11: 0.013888889 | W11: 0.013888889 | X11: 0.052083333 | Y11: 0.052083333 | Z11: 0.052083333 | AA11: 0.013888889 | AB11: 0.052083333 | AC11: 0.052083333 | AD11: 0.013888889
I12: DETERGENTE CLEAR 5L | J12: 0.013888889 | K12: 0.052083333 | L12: 0.052083333 | M12: 0.052083333 | N12: 0.013888889 | O12: 0.013888889 | P12: 0.013888889 | Q12: 0.013888889 | R12: 0.013888889 | S12: 0.013888889 | T12: 0.0069444444 | U12: 0.0069444444 | V12: 0.0069444444 | W12: 0.0069444444 | X12: 0.052083333 | Y12: 0.052083333 | Z12: 0.052083333 | AA12: 0.013888889 | AB12: 0.052083333 | AC12: 0.052083333 | AD12: 0.013888889
I13: DETERGENTE LIMAO 5L | J13: 0.013888889 | K13: 0.052083333 | L13: 0.052083333 | M13: 0.052083333 | N13: 0.013888889 | O13: 0.013888889 | P13: 0.013888889 | Q13: 0.013888889 | R13: 0.013888889 | S13: 0.013888889 | T13: 0.0069444444 | U13: 0.0069444444 | V13: 0.0069444444 | W13: 0.0069444444 | X13: 0.052083333 | Y13: 0.052083333 | Z13: 0.052083333 | AA13: 0.013888889 | AB13: 0.052083333 | AC13: 0.052083333 | AD13: 0.013888889
I14: DETERGENTE MAÇA 5L | J14: 0.013888889 | K14: 0.052083333 | L14: 0.052083333 | M14: 0.052083333 | N14: 0.013888889 | O14: 0.013888889 | P14: 0.013888889 | Q14: 0.013888889 | R14: 0.013888889 | S14: 0.013888889 | T14: 0.0069444444 | U14: 0.0069444444 | V14: 0.0069444444 | W14: 0.0069444444 | X14: 0.052083333 | Y14: 0.052083333 | Z14: 0.052083333 | AA14: 0.013888889 | AB14: 0.052083333 | AC14: 0.052083333 | AD14: 0.013888889
I15: DETERGENTE NEUTRO 5L | J15: 0.013888889 | K15: 0.052083333 | L15: 0.052083333 | M15: 0.052083333 | N15: 0.013888889 | O15: 0.013888889 | P15: 0.013888889 | Q15: 0.013888889 | R15: 0.013888889 | S15: 0.013888889 | T15: 0.0069444444 | U15: 0.0069444444 | V15: 0.0069444444 | W15: 0.0069444444 | X15: 0.052083333 | Y15: 0.052083333 | Z15: 0.052083333 | AA15: 0.013888889 | AB15: 0.052083333 | AC15: 0.052083333 | AD15: 0.013888889
I16: LAVA ROUPAS COCO 3L | J16: 0.052083333 | K16: 0.013888889 | L16: 0.013888889 | M16: 0.013888889 | N16: 0.052083333 | O16: 0.052083333 | P16: 0.052083333 | Q16: 0.052083333 | R16: 0.052083333 | S16: 0.052083333 | T16: 0.052083333 | U16: 0.052083333 | V16: 0.052083333 | W16: 0.052083333 | X16: 0.0069444444 | Y16: 0.0069444444 | Z16: 0.0069444444 | AA16: 0.052083333 | AB16: 0.0069444444 | AC16: 0.0069444444 | AD16: 0.052083333
I17: LAVA ROUPAS GLICERINA 3L | J17: 0.052083333 | K17: 0.013888889 | L17: 0.013888889 | M17: 0.013888889 | N17: 0.052083333 | O17: 0.052083333 | P17: 0.052083333 | Q17: 0.052083333 | R17: 0.052083333 | S17: 0.052083333 | T17: 0.052083333 | U17: 0.052083333 | V17: 0.052083333 | W17: 0.052083333 | X17: 0.0069444444 | Y17: 0.0069444444 | Z17: 0.0069444444 | AA17: 0.052083333 | AB17: 0.0069444444 | AC17: 0.0069444444 | AD17: 0.052083333
I18: LAVA ROUPAS MULTI ACAO 3L | J18: 0.052083333 | K18: 0.013888889 | L18: 0.013888889 | M18: 0.013888889 | N18: 0.052083333 | O18: 0.052083333 | P18: 0.052083333 | Q18: 0.052083333 | R18: 0.052083333 | S18: 0.052083333 | T18: 0.052083333 | U18: 0.052083333 | V18: 0.052083333 | W18: 0.052083333 | X18: 0.0069444444 | Y18: 0.0069444444 | Z18: 0.0069444444 | AA18: 0.052083333 | AB18: 0.0069444444 | AC18: 0.0069444444 | AD18: 0.052083333
I19: LAVA ROUPAS MULTI ACAO 5L | J19: 0.013888889 | K19: 0.052083333 | L19: 0.052083333 | M19: 0.052083333 | N19: 0.013888889 | O19: 0.013888889 | P19: 0.013888889 | Q19: 0.013888889 | R19: 0.013888889 | S19: 0.013888889 | T19: 0.013888889 | U19: 0.013888889 | V19: 0.013888889 | W19: 0.013888889 | X19: 0.052083333 | Y19: 0.052083333 | Z19: 0.052083333 | AA19: 0.0069444444 | AB19: 0.052083333 | AC19: 0.052083333 | AD19: 0.0069444444
... I22: LAVA ROUPAS TERNURA 5L | J22: 0.013888889 | K22: 0.052083333 | L22: 0.052083333 | M22: 0.052083333 | N22: 0.013888889 | O22: 0.013888889 | P22: 0.013888889 | Q22: 0.013888889 | R22: 0.013888889 | S22: 0.013888889 | T22: 0.013888889 | U22: 0.013888889 | V22: 0.013888889 | W22: 0.013888889 | X22: 0.052083333 | Y22: 0.052083333 | Z22: 0.052083333 | AA22: 0.0069444444 | AB22: 0.052083333 | AC22: 0.052083333 | AD22: 0.0069444444
A25: ALVEJANTE S/ CLORO 5L | I25: ALVEJANTE S/ CLORO 5L | K25: =CONCATENATE($A$25,$I25) -> ALVEJANTE S/ CLORO 5LALVEJANTE S/ CLORO 5L | L25: 0.0069444444
A26: AMAC. CONC. BRANCO TERNURA 3L | I26: AMAC. CONC. BRANCO TERNURA 3L | K26: =CONCATENATE($A$25,$I26) -> ALVEJANTE S/ CLORO 5LAMAC. CONC. BRANCO TERNURA 3L | L26: 0.052083333
A27: AMAC. CONC. ROSA ROMANCE 3L | I27: AMAC. CONC. ROSA ROMANCE 3L | K27: =CONCATENATE($A$25,$I27) -> ALVEJANTE S/ CLORO 5LAMAC. CONC. ROSA ROMANCE 3L | L27: 0.052083333
A28: AMAC. CONC. VERMELHO SEDUCAO 3L | I28: AMAC. CONC. VERMELHO SEDUCAO 3L | K28: =CONCATENATE($A$25,$I28) -> ALVEJANTE S/ CLORO 5LAMAC. CONC. VERMELHO SEDUCAO 3L | L28: 0.052083333
A29: AMACIANTE AZUL FRESC. MANHA 5L | I29: AMACIANTE AZUL FRESC. MANHA 5L | K29: =CONCATENATE($A$25,$I29) -> ALVEJANTE S/ CLORO 5LAMACIANTE AZUL FRESC. MANHA 5L | L29: 0.013888889
A30: AMACIANTE BRANCO PURA CARIC. 5L | I30: AMACIANTE BRANCO PURA CARIC. 5L | K30: =CONCATENATE($A$25,$I30) -> ALVEJANTE S/ CLORO 5LAMACIANTE BRANCO PURA CARIC. 5L | L30: 0.013888889
A31: AMACIANTE ENERGIA 5L | I31: AMACIANTE ENERGIA 5L | K31: =CONCATENATE($A$25,$I31) -> ALVEJANTE S/ CLORO 5LAMACIANTE ENERGIA 5L | L31: 0.013888889
A32: AMACIANTE ROSA JARD. FLORID 5L | I32: AMACIANTE ROSA JARD. FLORID 5L | K32: =CONCATENATE($A$25,$I32) -> ALVEJANTE S/ CLORO 5LAMACIANTE ROSA JARD. FLORID 5L | L32: 0.013888889
A33: AMACIANTE ROXO MAGIA 5L | I33: AMACIANTE ROXO MAGIA 5L | K33: =CONCATENATE($A$25,$I33) -> ALVEJANTE S/ CLORO 5LAMACIANTE ROXO MAGIA 5L | L33: 0.013888889
A34: AMACIANTE VERMELHO SEDUCAO 5L | I34: AMACIANTE VERMELHO SEDUCAO 5L | K34: =CONCATENATE($A$25,$I34) -> ALVEJANTE S/ CLORO 5LAMACIANTE VERMELHO SEDUCAO 5L | L34: 0.013888889
A35: DETERGENTE CLEAR 5L | I35: DETERGENTE CLEAR 5L | K35: =CONCATENATE($A$25,$I35) -> ALVEJANTE S/ CLORO 5LDETERGENTE CLEAR 5L | L35: 0.013888889
A36: DETERGENTE LIMAO 5L | I36: DETERGENTE LIMAO 5L | K36: =CONCATENATE($A$25,$I36) -> ALVEJANTE S/ CLORO 5LDETERGENTE LIMAO 5L | L36: 0.013888889
... A45: LAVA ROUPAS TERNURA 5L | I45: LAVA ROUPAS TERNURA 5L | K45: =CONCATENATE($A$25,$I45) -> ALVEJANTE S/ CLORO 5LLAVA ROUPAS TERNURA 5L | L45: 0.013888889
K46: =CONCATENATE($A$26,$I25) -> AMAC. CONC. BRANCO TERNURA 3LALVEJANTE S/ CLORO 5L | L46: 0.052083333
K47: =CONCATENATE($A$26,$I26) -> AMAC. CONC. BRANCO TERNURA 3LAMAC. CONC. BRANCO TERNURA 3L | L47: 0.0069444444
K48: =CONCATENATE($A$26,$I27) -> AMAC. CONC. BRANCO TERNURA 3LAMAC. CONC. ROSA ROMANCE 3L | L48: 0.0069444444
K49: =CONCATENATE($A$26,$I28) -> AMAC. CONC. BRANCO TERNURA 3LAMAC. CONC. VERMELHO SEDUCAO 3L | L49: 0.0069444444
K50: =CONCATENATE($A$26,$I29) -> AMAC. CONC. BRANCO TERNURA 3LAMACIANTE AZUL FRESC. MANHA 5L | L50: 0.052083333
K51: =CONCATENATE($A$26,$I30) -> AMAC. CONC. BRANCO TERNURA 3LAMACIANTE BRANCO PURA CARIC. 5L | L51: 0.052083333
K52: =CONCATENATE($A$26,$I31) -> AMAC. CONC. BRANCO TERNURA 3LAMACIANTE ENERGIA 5L | L52: 0.052083333
...

Sheet Linha 6
A1: LINHA 06 | B1: AMAC. CONC. 1,5L | C1: AMAC. CONC. 1L | D1: AMAC. CONC. 500ML | E1: DESENG. PULVER. 500ML | F1: DESENG. RECARGA 500ML | G1: DESENG. SQUEEZE 1L | H1: DESENG. SQUEEZE 500ML | I1: LAVA ROUPAS 1L | J1: LIMP PERF 1L | K1: LIMP PERF 500ML | L1: LIMPA VIDROS PULVER. 500ML | M1: LIMPA VIDROS RECARGA 500ML | N1: LIMPA VIDROS SQUEEZE 500ML | O1: MULTI USO 1L | P1: MULTI USO 500ML | S1: AMAC. CONC. AZUL HARMONIA 1,5L | T1: AMAC. CONC. AZUL HARMONIA 1L | U1: AMAC. CONC. AZUL HARMONIA 500ML | V1: AMAC. CONC. BRANCO TERNURA 1,5L | W1: AMAC. CONC. BRANCO TERNURA 1L | X1: AMAC. CONC. BRANCO TERNURA 500ML | Y1: AMAC. CONC. DOURADO INSPIRACAO 1L | Z1: AMAC. CONC. ROSA ROMANCE 1,5L | AA1: AMAC. CONC. ROSA ROMANCE 1L | AB1: AMAC. CONC. ROSA ROMANCE 500ML | AC1: AMAC. CONC. SPORTS 1,5L | AD1: AMAC. CONC. VERMELHO SEDUC 1,5L | AE1: AMAC. CONC. VERMELHO SEDUCAO 1L | AF1: AMAC. CONC. VERMELHO SEDUCAO 500ML | AG1: DESENGORDURANTE PULVERIZADOR 500ML | AH1: DESENGORDURANTE RECARGA 500ML | AI1: DESENGORDURANTE SQUEEZE 1L | AJ1: DESENGORDURANTE SQUEEZE 500ML | AK1: LAVA ROUPAS BABY 1L | AL1: LAVA ROUPAS GLICERINA 1L | AM1: LAVA ROUPAS MULTI ACAO 1L | AN1: LIMP PERF DOCE ROMANCE 1L | AO1: LIMP PERF DOCE ROMANCE 500ML | AP1: LIMP PERF ESSENCIA NATURAL 1L | AQ1: LIMP PERF FLORES CAMPESTRES 1L | AR1: LIMP PERF FRESCOR DA MANHA 1L | AS1: LIMP PERF FRESCOR DA MANHA 500ML | AT1: LIMP PERF MAGIA DA INFANCIA 1L | AU1: LIMP PERF MAGIA DA INFANCIA 500ML | AV1: LIMP PERF MAGIA SEDUCAO 1L | AW1: LIMP PERF MAGIA SEDUCAO 500ML | AX1: LIMP PERF PRIMAVERA FLORIDA 1L | AY1: LIMPA VIDROS PULVERIZADOR 500ML | AZ1: LIMPA VIDROS RECARGA 500ML | BA1: LIMPA VIDROS SQUEEZE 500ML | BB1: MULTI USO LAVANDA C/ ALCOOL 500ML | BC1: MULTI USO ORIGINAL C/ BICARB. 1L | BD1: MULTI USO ORIGINAL C/ BICARB. 500ML | BE1: MULTI USO ROMANCE 1L | BF1: MULTI USO ROMANCE 500ML | BG1: MULTI USO SEDUCAO 1L | BH1: MULTI USO SEDUCAO 500ML | BI1: MULTIUSO LAVANDA C/ ALCOOL 1L
A2: AMAC. CONC. 1,5L | B2: 0.010416667 | C2: 0.027777778 | D2: 0.027777778 | E2: 0.027777778 | F2: 0.027777778 | G2: 0.027777778 | H2: 0.027777778 | I2: 0.027777778 | J2: 0.027777778 | K2: 0.027777778 | L2: 0.027777778 | M2: 0.027777778 | N2: 0.027777778 | O2: 0.027777778 | P2: 0.027777778 | R2: AMAC. CONC. AZUL HARMONIA 1,5L | S2: 0.010416667 | T2: 0.027777778 | U2: 0.027777778 | V2: 0.010416667 | W2: 0.027777778 | X2: 0.027777778 | Y2: 0.027777778 | Z2: 0.010416667 | AA2: 0.027777778 | AB2: 0.027777778 | AC2: 0.010416667 | AD2: 0.010416667 | AE2: 0.027777778 | AF2: 0.027777778 | AG2: 0.027777778 | AH2: 0.027777778 | AI2: 0.027777778 | AJ2: 0.027777778 | AK2: 0.027777778 | AL2: 0.027777778 | AM2: 0.027777778 | AN2: 0.027777778 | AO2: 0.027777778 | AP2: 0.027777778 | AQ2: 0.027777778 | AR2: 0.027777778 | AS2: 0.027777778 | AT2: 0.027777778 | AU2: 0.027777778 | AV2: 0.027777778 | AW2: 0.027777778 | AX2: 0.027777778 | AY2: 0.027777778 | AZ2: 0.027777778 | BA2: 0.027777778 | BB2: 0.027777778 | BC2: 0.027777778 | BD2: 0.027777778 | BE2: 0.027777778 | BF2: 0.027777778 | BG2: 0.027777778 | BH2: 0.027777778 | BI2: 0.027777778
A3: AMAC. CONC. 1L | B3: 0.027777778 | C3: 0.010416667 | D3: 0.027777778 | E3: 0.027777778 | F3: 0.027777778 | G3: 0.027777778 | H3: 0.027777778 | I3: 0.027777778 | J3: 0.027777778 | K3: 0.027777778 | L3: 0.027777778 | M3: 0.027777778 | N3: 0.027777778 | O3: 0.027777778 | P3: 0.027777778 | R3: AMAC. CONC. AZUL HARMONIA 1L | S3: 0.027777778 | T3: 0.010416667 | U3: 0.027777778 | V3: 0.027777778 | W3: 0.010416667 | X3: 0.027777778 | Y3: 0.010416667 | Z3: 0.027777778 | AA3: 0.010416667 | AB3: 0.027777778 | AC3: 0.027777778 | AD3: 0.027777778 | AE3: 0.010416667 | AF3: 0.027777778 | AG3: 0.027777778 | AH3: 0.027777778 | AI3: 0.020833333 | AJ3: 0.027777778 | AK3: 0.020833333 | AL3: 0.020833333 | AM3: 0.020833333 | AN3: 0.020833333 | AO3: 0.027777778 | AP3: 0.020833333 | AQ3: 0.020833333 | AR3: 0.020833333 | AS3: 0.027777778 | AT3: 0.020833333 | AU3: 0.027777778 | AV3: 0.020833333 | AW3: 0.027777778 | AX3: 0.020833333 | AY3: 0.027777778 | AZ3: 0.027777778 | BA3: 0.027777778 | BB3: 0.027777778 | BC3: 0.020833333 | BD3: 0.027777778 | BE3: 0.020833333 | BF3: 0.027777778 | BG3: 0.020833333 | BH3: 0.027777778 | BI3: 0.020833333
A4: AMAC. CONC. 500ML | B4: 0.027777778 | C4: 0.020833333 | D4: 0.010416667 | E4: 0.020833333 | F4: 0.020833333 | G4: 0.027777778 | H4: 0.020833333 | I4: 0.027777778 | J4: 0.027777778 | K4: 0.020833333 | L4: 0.020833333 | M4: 0.020833333 | N4: 0.020833333 | O4: 0.027777778 | P4: 0.020833333 | R4: AMAC. CONC. AZUL HARMONIA 500ML | S4: 0.027777778 | T4: 0.027777778 | U4: 0.010416667 | V4: 0.027777778 | W4: 0.027777778 | X4: 0.010416667 | Y4: 0.027777778 | Z4: 0.027777778 | AA4: 0.027777778 | AB4: 0.010416667 | AC4: 0.027777778 | AD4: 0.027777778 | AE4: 0.027777778 | AF4: 0.010416667 | AG4: 0.020833333 | AH4: 0.020833333 | AI4: 0.027777778 | AJ4: 0.020833333 | AK4: 0.027777778 | AL4: 0.027777778 | AM4: 0.027777778 | AN4: 0.027777778 | AO4: 0.020833333 | AP4: 0.027777778 | AQ4: 0.027777778 | AR4: 0.027777778 | AS4: 0.020833333 | AT4: 0.027777778 | AU4: 0.020833333 | AV4: 0.027777778 | AW4: 0.020833333 | AX4: 0.027777778 | AY4: 0.020833333 | AZ4: 0.020833333 | BA4: 0.020833333 | BB4: 0.020833333 | BC4: 0.027777778 | BD4: 0.020833333 | BE4: 0.027777778 | BF4: 0.020833333 | BG4: 0.027777778 | BH4: 0.020833333 | BI4: 0.027777778
A5: DESENG. PULVER. 500ML | B5: 0.027777778 | C5: 0.027777778 | D5: 0.020833333 | E5: 0.010416667 | F5: 0.010416667 | G5: 0.027777778 | H5: 0.010416667 | I5: 0.027777778 | J5: 0.027777778 | K5: 0.020833333 | L5: 0.020833333 | M5: 0.020833333 | N5: 0.020833333 | O5: 0.027777778 | P5: 0.020833333 | R5: AMAC. CONC. BRANCO TERNURA 1,5L | S5: 0.010416667 | T5: 0.027777778 | U5: 0.027777778 | V5: 0.010416667 | W5: 0.027777778 | X5: 0.027777778 | Y5: 0.027777778 | Z5: 0.010416667 | AA5: 0.027777778 | AB5: 0.027777778 | AC5: 0.010416667 | AD5: 0.010416667 | AE5: 0.027777778 | AF5: 0.027777778 | AG5: 0.027777778 | AH5: 0.027777778 | AI5: 0.027777778 | AJ5: 0.027777778 | AK5: 0.027777778 | AL5: 0.027777778 | AM5: 0.027777778 | AN5: 0.027777778 | AO5: 0.027777778 | AP5: 0.027777778 | AQ5: 0.027777778 | AR5: 0.027777778 | AS5: 0.027777778 | AT5: 0.027777778 | AU5: 0.027777778 | AV5: 0.027777778 | AW5: 0.027777778 | AX5: 0.027777778 | AY5: 0.027777778 | AZ5: 0.027777778 | BA5: 0.027777778 | BB5: 0.027777778 | BC5: 0.027777778 | BD5: 0.027777778 | BE5: 0.027777778 | BF5: 0.027777778 | BG5: 0.027777778 | BH5: 0.027777778 | BI5: 0.027777778
A6: DESENG. RECARGA 500ML | B6: 0.027777778 | C6: 0.027777778 | D6: 0.020833333 | E6: 0.010416667 | F6: 0.010416667 | G6: 0.027777778 | H6: 0.010416667 | I6: 0.027777778 | J6: 0.027777778 | K6: 0.020833333 | L6: 0.020833333 | M6: 0.020833333 | N6: 0.020833333 | O6: 0.027777778 | P6: 0.020833333 | R6: AMAC. CONC. BRANCO TERNURA 1L | S6: 0.027777778 | T6: 0.010416667 | U6: 0.027777778 | V6: 0.027777778 | W6: 0.010416667 | X6: 0.027777778 | Y6: 0.010416667 | Z6: 0.027777778 | AA6: 0.010416667 | AB6: 0.027777778 | AC6: 0.027777778 | AD6: 0.027777778 | AE6: 0.010416667 | AF6: 0.027777778 | AG6: 0.027777778 | AH6: 0.027777778 | AI6: 0.020833333 | AJ6: 0.027777778 | AK6: 0.020833333 | AL6: 0.020833333 | AM6: 0.020833333 | AN6: 0.020833333 | AO6: 0.027777778 | AP6: 0.020833333 | AQ6: 0.020833333 | AR6: 0.020833333 | AS6: 0.027777778 | AT6: 0.020833333 | AU6: 0.027777778 | AV6: 0.020833333 | AW6: 0.027777778 | AX6: 0.020833333 | AY6: 0.027777778 | AZ6: 0.027777778 | BA6: 0.027777778 | BB6: 0.027777778 | BC6: 0.020833333 | BD6: 0.027777778 | BE6: 0.020833333 | BF6: 0.027777778 | BG6: 0.020833333 | BH6: 0.027777778 | BI6: 0.020833333
A7: DESENG. SQUEEZE 1L | B7: 0.027777778 | C7: 0.020833333 | D7: 0.027777778 | E7: 0.027777778 | F7: 0.027777778 | G7: 0.010416667 | H7: 0.027777778 | I7: 0.020833333 | J7: 0.020833333 | K7: 0.027777778 | L7: 0.027777778 | M7: 0.027777778 | N7: 0.027777778 | O7: 0.020833333 | P7: 0.027777778 | R7: AMAC. CONC. BRANCO TERNURA 500ML | S7: 0.027777778 | T7: 0.027777778 | U7: 0.010416667 | V7: 0.027777778 | W7: 0.027777778 | X7: 0.010416667 | Y7: 0.027777778 | Z7: 0.027777778 | AA7: 0.027777778 | AB7: 0.010416667 | AC7: 0.027777778 | AD7: 0.027777778 | AE7: 0.027777778 | AF7: 0.010416667 | AG7: 0.020833333 | AH7: 0.020833333 | AI7: 0.027777778 | AJ7: 0.020833333 | AK7: 0.027777778 | AL7: 0.027777778 | AM7: 0.027777778 | AN7: 0.027777778 | AO7: 0.020833333 | AP7: 0.027777778 | AQ7: 0.027777778 | AR7: 0.027777778 | AS7: 0.020833333 | AT7: 0.027777778 | AU7: 0.020833333 | AV7: 0.027777778 | AW7: 0.020833333 | AX7: 0.027777778 | AY7: 0.020833333 | AZ7: 0.020833333 | BA7: 0.020833333 | BB7: 0.020833333 | BC7: 0.027777778 | BD7: 0.020833333 | BE7: 0.027777778 | BF7: 0.020833333 | BG7: 0.027777778 | BH7: 0.020833333 | BI7: 0.027777778
A8: DESENG. SQUEEZE 500ML | B8: 0.027777778 | C8: 0.027777778 | D8: 0.020833333 | E8: 0.010416667 | F8: 0.010416667 | G8: 0.027777778 | H8: 0.010416667 | I8: 0.027777778 | J8: 0.027777778 | K8: 0.020833333 | L8: 0.020833333 | M8: 0.020833333 | N8: 0.020833333 | O8: 0.027777778 | P8: 0.010416667 | R8: AMAC. CONC. DOURADO INSPIRACAO 1L | S8: 0.027777778 | T8: 0.010416667 | U8: 0.027777778 | V8: 0.027777778 | W8: 0.010416667 | X8: 0.027777778 | Y8: 0.010416667 | Z8: 0.027777778 | AA8: 0.010416667 | AB8: 0.027777778 | AC8: 0.027777778 | AD8: 0.027777778 | AE8: 0.010416667 | AF8: 0.027777778 | AG8: 0.027777778 | AH8: 0.027777778 | AI8: 0.020833333 | AJ8: 0.027777778 | AK8: 0.020833333 | AL8: 0.020833333 | AM8: 0.020833333 | AN8: 0.020833333 | AO8: 0.027777778 | AP8: 0.020833333 | AQ8: 0.020833333 | AR8: 0.020833333 | AS8: 0.027777778 | AT8: 0.020833333 | AU8: 0.027777778 | AV8: 0.020833333 | AW8: 0.027777778 | AX8: 0.020833333 | AY8: 0.027777778 | AZ8: 0.027777778 | BA8: 0.027777778 | BB8: 0.027777778 | BC8: 0.020833333 | BD8: 0.027777778 | BE8: 0.020833333 | BF8: 0.027777778 | BG8: 0.020833333 | BH8: 0.027777778 | BI8: 0.020833333
A9: LAVA ROUPAS 1L | B9: 0.027777778 | C9: 0.020833333 | D9: 0.027777778 | E9: 0.027777778 | F9: 0.027777778 | G9: 0.020833333 | H9: 0.027777778 | I9: 0.010416667 | J9: 0.020833333 | K9: 0.027777778 | L9: 0.027777778 | M9: 0.027777778 | N9: 0.027777778 | O9: 0.020833333 | P9: 0.027777778 | R9: AMAC. CONC. ROSA ROMANCE 1,5L | S9: 0.010416667 | T9: 0.027777778 | U9: 0.027777778 | V9: 0.010416667 | W9: 0.027777778 | X9: 0.027777778 | Y9: 0.027777778 | Z9: 0.010416667 | AA9: 0.027777778 | AB9: 0.027777778 | AC9: 0.010416667 | AD9: 0.010416667 | AE9: 0.027777778 | AF9: 0.027777778 | AG9: 0.027777778 | AH9: 0.027777778 | AI9: 0.027777778 | AJ9: 0.027777778 | AK9: 0.027777778 | AL9: 0.027777778 | AM9: 0.027777778 | AN9: 0.027777778 | AO9: 0.027777778 | AP9: 0.027777778 | AQ9: 0.027777778 | AR9: 0.027777778 | AS9: 0.027777778 | AT9: 0.027777778 | AU9: 0.027777778 | AV9: 0.027777778 | AW9: 0.027777778 | AX9: 0.027777778 | AY9: 0.027777778 | AZ9: 0.027777778 | BA9: 0.027777778 | BB9: 0.027777778 | BC9: 0.027777778 | BD9: 0.027777778 | BE9: 0.027777778 | BF9: 0.027777778 | BG9: 0.027777778 | BH9: 0.027777778 | BI9: 0.027777778
A10: LIMP PERF 1L | B10: 0.027777778 | C10: 0.027777778 | D10: 0.027777778 | E10: 0.027777778 | F10: 0.027777778 | G10: 0.020833333 | H10: 0.027777778 | I10: 0.020833333 | J10: 0.010416667 | K10: 0.027777778 | L10: 0.027777778 | M10: 0.027777778 | N10: 0.027777778 | O10: 0.020833333 | P10: 0.020833333 | R10: AMAC. CONC. ROSA ROMANCE 1L | S10: 0.027777778 | T10: 0.010416667 | U10: 0.027777778 | V10: 0.027777778 | W10: 0.010416667 | X10: 0.027777778 | Y10: 0.010416667 | Z10: 0.027777778 | AA10: 0.010416667 | AB10: 0.027777778 | AC10: 0.027777778 | AD10: 0.027777778 | AE10: 0.010416667 | AF10: 0.027777778 | AG10: 0.027777778 | AH10: 0.027777778 | AI10: 0.020833333 | AJ10: 0.027777778 | AK10: 0.020833333 | AL10: 0.020833333 | AM10: 0.020833333 | AN10: 0.020833333 | AO10: 0.027777778 | AP10: 0.020833333 | AQ10: 0.020833333 | AR10: 0.020833333 | AS10: 0.027777778 | AT10: 0.020833333 | AU10: 0.027777778 | AV10: 0.020833333 | AW10: 0.027777778 | AX10: 0.020833333 | AY10: 0.027777778 | AZ10: 0.027777778 | BA10: 0.027777778 | BB10: 0.027777778 | BC10: 0.020833333 | BD10: 0.027777778 | BE10: 0.020833333 | BF10: 0.027777778 | BG10: 0.020833333 | BH10: 0.027777778 | BI10: 0.020833333
A11: LIMP PERF 500ML | B11: 0.027777778 | C11: 0.027777778 | D11: 0.020833333 | E11: 0.020833333 | F11: 0.020833333 | G11: 0.027777778 | H11: 0.020833333 | I11: 0.027777778 | J11: 0.027777778 | K11: 0.010416667 | L11: 0.020833333 | M11: 0.020833333 | N11: 0.020833333 | O11: 0.027777778 | P11: 0.020833333 | R11: AMAC. CONC. ROSA ROMANCE 500ML | S11: 0.027777778 | T11: 0.027777778 | U11: 0.010416667 | V11: 0.027777778 | W11: 0.027777778 | X11: 0.010416667 | Y11: 0.027777778 | Z11: 0.027777778 | AA11: 0.027777778 | AB11: 0.010416667 | AC11: 0.027777778 | AD11: 0.027777778 | AE11: 0.027777778 | AF11: 0.010416667 | AG11: 0.020833333 | AH11: 0.020833333 | AI11: 0.027777778 | AJ11: 0.020833333 | AK11: 0.027777778 | AL11: 0.027777778 | AM11: 0.027777778 | AN11: 0.027777778 | AO11: 0.020833333 | AP11: 0.027777778 | AQ11: 0.027777778 | AR11: 0.027777778 | AS11: 0.020833333 | AT11: 0.027777778 | AU11: 0.020833333 | AV11: 0.027777778 | AW11: 0.020833333 | AX11: 0.027777778 | AY11: 0.020833333 | AZ11: 0.020833333 | BA11: 0.020833333 | BB11: 0.020833333 | BC11: 0.027777778 | BD11: 0.020833333 | BE11: 0.027777778 | BF11: 0.020833333 | BG11: 0.027777778 | BH11: 0.020833333 | BI11: 0.027777778
A12: LIMPA VIDROS PULVER. 500ML | B12: 0.027777778 | C12: 0.027777778 | D12: 0.020833333 | E12: 0.020833333 | F12: 0.020833333 | G12: 0.027777778 | H12: 0.020833333 | I12: 0.027777778 | J12: 0.027777778 | K12: 0.020833333 | L12: 0.010416667 | M12: 0.010416667 | N12: 0.010416667 | O12: 0.027777778 | P12: 0.020833333 | R12: AMAC. CONC. SPORTS 1,5L | S12: 0.010416667 | T12: 0.027777778 | U12: 0.027777778 | V12: 0.010416667 | W12: 0.027777778 | X12: 0.027777778 | Y12: 0.027777778 | Z12: 0.010416667 | AA12: 0.027777778 | AB12: 0.027777778 | AC12: 0.010416667 | AD12: 0.010416667 | AE12: 0.027777778 | AF12: 0.027777778 | AG12: 0.027777778 | AH12: 0.027777778 | AI12: 0.027777778 | AJ12: 0.027777778 | AK12: 0.027777778 | AL12: 0.027777778 | AM12: 0.027777778 | AN12: 0.027777778 | AO12: 0.027777778 | AP12: 0.027777778 | AQ12: 0.027777778 | AR12: 0.027777778 | AS12: 0.027777778 | AT12: 0.027777778 | AU12: 0.027777778 | AV12: 0.027777778 | AW12: 0.027777778 | AX12: 0.027777778 | AY12: 0.027777778 | AZ12: 0.027777778 | BA12: 0.027777778 | BB12: 0.027777778 | BC12: 0.027777778 | BD12: 0.027777778 | BE12: 0.027777778 | BF12: 0.027777778 | BG12: 0.027777778 | BH12: 0.027777778 | BI12: 0.027777778
